[2025-03-28T16:36:07.983+0000] {local_task_job_runner.py:123} INFO - ::group::Pre task execution logs
[2025-03-28T16:36:08.007+0000] {taskinstance.py:2612} INFO - Dependencies all met for dep_context=non-requeueable deps ti=<TaskInstance: superstore_dag.forecast_aggregate_sales manual__2025-03-28T16:35:44.841886+00:00 [queued]>
[2025-03-28T16:36:08.021+0000] {taskinstance.py:2612} INFO - Dependencies all met for dep_context=requeueable deps ti=<TaskInstance: superstore_dag.forecast_aggregate_sales manual__2025-03-28T16:35:44.841886+00:00 [queued]>
[2025-03-28T16:36:08.024+0000] {taskinstance.py:2865} INFO - Starting attempt 1 of 2
[2025-03-28T16:36:08.066+0000] {taskinstance.py:2888} INFO - Executing <Task(PythonOperator): forecast_aggregate_sales> on 2025-03-28 16:35:44.841886+00:00
[2025-03-28T16:36:08.077+0000] {standard_task_runner.py:72} INFO - Started process 2653 to run task
[2025-03-28T16:36:08.082+0000] {standard_task_runner.py:104} INFO - Running: ['***', 'tasks', 'run', 'superstore_dag', 'forecast_aggregate_sales', 'manual__2025-03-28T16:35:44.841886+00:00', '--job-id', '112', '--raw', '--subdir', 'DAGS_FOLDER/superstore_dag.py', '--cfg-path', '/tmp/tmpvw9ssn46']
[2025-03-28T16:36:08.085+0000] {standard_task_runner.py:105} INFO - Job 112: Subtask forecast_aggregate_sales
[2025-03-28T16:36:08.161+0000] {task_command.py:467} INFO - Running <TaskInstance: superstore_dag.forecast_aggregate_sales manual__2025-03-28T16:35:44.841886+00:00 [running]> on host b7fc87b83960
[2025-03-28T16:36:08.300+0000] {taskinstance.py:3131} INFO - Exporting env vars: AIRFLOW_CTX_DAG_OWNER='***' AIRFLOW_CTX_DAG_ID='superstore_dag' AIRFLOW_CTX_TASK_ID='forecast_aggregate_sales' AIRFLOW_CTX_EXECUTION_DATE='2025-03-28T16:35:44.841886+00:00' AIRFLOW_CTX_TRY_NUMBER='1' AIRFLOW_CTX_DAG_RUN_ID='manual__2025-03-28T16:35:44.841886+00:00'
[2025-03-28T16:36:08.302+0000] {logging_mixin.py:190} INFO - Task instance is in running state
[2025-03-28T16:36:08.305+0000] {logging_mixin.py:190} INFO -  Previous state of the Task instance: queued
[2025-03-28T16:36:08.307+0000] {logging_mixin.py:190} INFO - Current task name:forecast_aggregate_sales state:running start_date:2025-03-28 16:36:08.009743+00:00
[2025-03-28T16:36:08.310+0000] {logging_mixin.py:190} INFO - Dag name:superstore_dag and current dag run status:running
[2025-03-28T16:36:08.312+0000] {taskinstance.py:731} INFO - ::endgroup::
[2025-03-28T16:36:08.373+0000] {forecaster.py:961} INFO - Disabling daily seasonality. Run prophet with daily_seasonality=True to override this.
[2025-03-28T16:36:08.399+0000] {filesystem.py:118} DEBUG - input tempfile: /tmp/tmpehbh39iq/k3d49z5k.json
[2025-03-28T16:36:08.479+0000] {filesystem.py:118} DEBUG - input tempfile: /tmp/tmpehbh39iq/541wj46z.json
[2025-03-28T16:36:08.483+0000] {model.py:2042} DEBUG - idx 0
[2025-03-28T16:36:08.485+0000] {model.py:2043} DEBUG - running CmdStan, num_threads: None
[2025-03-28T16:36:08.487+0000] {model.py:2055} DEBUG - CmdStan args: ['/home/***/.local/lib/python3.9/site-packages/prophet/stan_model/prophet_model.bin', 'random', 'seed=49818', 'data', 'file=/tmp/tmpehbh39iq/k3d49z5k.json', 'init=/tmp/tmpehbh39iq/541wj46z.json', 'output', 'file=/tmp/tmpehbh39iq/prophet_modelbbayltcv/prophet_model-20250328163608.csv', 'method=optimize', 'algorithm=lbfgs', 'iter=10000']
[2025-03-28T16:36:08.490+0000] {logging_mixin.py:190} WARNING - 16:36:08 - cmdstanpy - INFO - Chain [1] start processing
[2025-03-28T16:36:08.490+0000] {model.py:2058} INFO - Chain [1] start processing
[2025-03-28T16:36:08.555+0000] {logging_mixin.py:190} WARNING - 16:36:08 - cmdstanpy - INFO - Chain [1] done processing
[2025-03-28T16:36:08.555+0000] {model.py:2115} INFO - Chain [1] done processing
[2025-03-28T16:36:08.914+0000] {taskinstance.py:3310} ERROR - Task failed with exception
Traceback (most recent call last):
  File "/home/airflow/.local/lib/python3.9/site-packages/airflow/models/taskinstance.py", line 767, in _execute_task
    result = _execute_callable(context=context, **execute_callable_kwargs)
  File "/home/airflow/.local/lib/python3.9/site-packages/airflow/models/taskinstance.py", line 733, in _execute_callable
    return ExecutionCallableRunner(
  File "/home/airflow/.local/lib/python3.9/site-packages/airflow/utils/operator_helpers.py", line 252, in run
    return self.func(*args, **kwargs)
  File "/home/airflow/.local/lib/python3.9/site-packages/airflow/models/baseoperator.py", line 406, in wrapper
    return func(self, *args, **kwargs)
  File "/home/airflow/.local/lib/python3.9/site-packages/airflow/operators/python.py", line 238, in execute
    return_value = self.execute_callable()
  File "/home/airflow/.local/lib/python3.9/site-packages/airflow/operators/python.py", line 256, in execute_callable
    return runner.run(*self.op_args, **self.op_kwargs)
  File "/home/airflow/.local/lib/python3.9/site-packages/airflow/utils/operator_helpers.py", line 252, in run
    return self.func(*args, **kwargs)
  File "/opt/airflow/dags/superstore_dag.py", line 194, in forecast_aggregate_sales
    forecast_df=forecast.Dataframe()
  File "/home/airflow/.local/lib/python3.9/site-packages/pandas/core/generic.py", line 6204, in __getattr__
    return object.__getattribute__(self, name)
AttributeError: 'DataFrame' object has no attribute 'Dataframe'
[2025-03-28T16:36:08.938+0000] {logging_mixin.py:190} INFO - Task instance in failure state
[2025-03-28T16:36:08.941+0000] {logging_mixin.py:190} INFO - Task start:2025-03-28 16:36:08.009743+00:00 end:2025-03-28 16:36:08.938149+00:00 duration:0.928406
[2025-03-28T16:36:08.942+0000] {logging_mixin.py:190} INFO - Task:<Task(PythonOperator): forecast_aggregate_sales> dag:<DAG: superstore_dag> dagrun:<DagRun superstore_dag @ 2025-03-28 16:35:44.841886+00:00: manual__2025-03-28T16:35:44.841886+00:00, state:running, queued_at: 2025-03-28 16:35:44.874691+00:00. externally triggered: True>
[2025-03-28T16:36:08.944+0000] {logging_mixin.py:190} INFO - Failure caused by 'DataFrame' object has no attribute 'Dataframe'
[2025-03-28T16:36:08.947+0000] {taskinstance.py:1225} INFO - Marking task as UP_FOR_RETRY. dag_id=superstore_dag, task_id=forecast_aggregate_sales, run_id=manual__2025-03-28T16:35:44.841886+00:00, execution_date=20250328T163544, start_date=20250328T163608, end_date=20250328T163608
[2025-03-28T16:36:08.987+0000] {taskinstance.py:340} INFO - ::group::Post task execution logs
[2025-03-28T16:36:08.990+0000] {standard_task_runner.py:124} ERROR - Failed to execute job 112 for task forecast_aggregate_sales ('DataFrame' object has no attribute 'Dataframe'; 2653)
Traceback (most recent call last):
  File "/home/airflow/.local/lib/python3.9/site-packages/airflow/task/task_runner/standard_task_runner.py", line 117, in _start_by_fork
    ret = args.func(args, dag=self.dag)
  File "/home/airflow/.local/lib/python3.9/site-packages/airflow/cli/cli_config.py", line 49, in command
    return func(*args, **kwargs)
  File "/home/airflow/.local/lib/python3.9/site-packages/airflow/utils/cli.py", line 115, in wrapper
    return f(*args, **kwargs)
  File "/home/airflow/.local/lib/python3.9/site-packages/airflow/cli/commands/task_command.py", line 483, in task_run
    task_return_code = _run_task_by_selected_method(args, _dag, ti)
  File "/home/airflow/.local/lib/python3.9/site-packages/airflow/cli/commands/task_command.py", line 256, in _run_task_by_selected_method
    return _run_raw_task(args, ti)
  File "/home/airflow/.local/lib/python3.9/site-packages/airflow/cli/commands/task_command.py", line 341, in _run_raw_task
    return ti._run_raw_task(
  File "/home/airflow/.local/lib/python3.9/site-packages/airflow/utils/session.py", line 97, in wrapper
    return func(*args, session=session, **kwargs)
  File "/home/airflow/.local/lib/python3.9/site-packages/airflow/models/taskinstance.py", line 3004, in _run_raw_task
    return _run_raw_task(
  File "/home/airflow/.local/lib/python3.9/site-packages/airflow/models/taskinstance.py", line 273, in _run_raw_task
    TaskInstance._execute_task_with_callbacks(
  File "/home/airflow/.local/lib/python3.9/site-packages/airflow/models/taskinstance.py", line 3158, in _execute_task_with_callbacks
    result = self._execute_task(context, task_orig)
  File "/home/airflow/.local/lib/python3.9/site-packages/airflow/models/taskinstance.py", line 3182, in _execute_task
    return _execute_task(self, context, task_orig)
  File "/home/airflow/.local/lib/python3.9/site-packages/airflow/models/taskinstance.py", line 767, in _execute_task
    result = _execute_callable(context=context, **execute_callable_kwargs)
  File "/home/airflow/.local/lib/python3.9/site-packages/airflow/models/taskinstance.py", line 733, in _execute_callable
    return ExecutionCallableRunner(
  File "/home/airflow/.local/lib/python3.9/site-packages/airflow/utils/operator_helpers.py", line 252, in run
    return self.func(*args, **kwargs)
  File "/home/airflow/.local/lib/python3.9/site-packages/airflow/models/baseoperator.py", line 406, in wrapper
    return func(self, *args, **kwargs)
  File "/home/airflow/.local/lib/python3.9/site-packages/airflow/operators/python.py", line 238, in execute
    return_value = self.execute_callable()
  File "/home/airflow/.local/lib/python3.9/site-packages/airflow/operators/python.py", line 256, in execute_callable
    return runner.run(*self.op_args, **self.op_kwargs)
  File "/home/airflow/.local/lib/python3.9/site-packages/airflow/utils/operator_helpers.py", line 252, in run
    return self.func(*args, **kwargs)
  File "/opt/airflow/dags/superstore_dag.py", line 194, in forecast_aggregate_sales
    forecast_df=forecast.Dataframe()
  File "/home/airflow/.local/lib/python3.9/site-packages/pandas/core/generic.py", line 6204, in __getattr__
    return object.__getattribute__(self, name)
AttributeError: 'DataFrame' object has no attribute 'Dataframe'
[2025-03-28T16:36:09.022+0000] {local_task_job_runner.py:266} INFO - Task exited with return code 1
[2025-03-28T16:36:09.053+0000] {taskinstance.py:3900} INFO - 0 downstream tasks scheduled from follow-on schedule check
[2025-03-28T16:36:09.076+0000] {local_task_job_runner.py:245} INFO - ::endgroup::
