[2025-03-27T23:36:45.628+0000] {local_task_job_runner.py:123} INFO - ::group::Pre task execution logs
[2025-03-27T23:36:45.650+0000] {taskinstance.py:2612} INFO - Dependencies all met for dep_context=non-requeueable deps ti=<TaskInstance: superstore_dag.load_data_to_prod_db manual__2025-03-27T23:36:31.455144+00:00 [queued]>
[2025-03-27T23:36:45.665+0000] {taskinstance.py:2612} INFO - Dependencies all met for dep_context=requeueable deps ti=<TaskInstance: superstore_dag.load_data_to_prod_db manual__2025-03-27T23:36:31.455144+00:00 [queued]>
[2025-03-27T23:36:45.669+0000] {taskinstance.py:2865} INFO - Starting attempt 1 of 2
[2025-03-27T23:36:45.707+0000] {taskinstance.py:2888} INFO - Executing <Task(PythonOperator): load_data_to_prod_db> on 2025-03-27 23:36:31.455144+00:00
[2025-03-27T23:36:45.716+0000] {standard_task_runner.py:72} INFO - Started process 306 to run task
[2025-03-27T23:36:45.720+0000] {standard_task_runner.py:104} INFO - Running: ['***', 'tasks', 'run', 'superstore_dag', 'load_data_to_prod_db', 'manual__2025-03-27T23:36:31.455144+00:00', '--job-id', '34', '--raw', '--subdir', 'DAGS_FOLDER/superstore_dag.py', '--cfg-path', '/tmp/tmp96_mchcs']
[2025-03-27T23:36:45.724+0000] {standard_task_runner.py:105} INFO - Job 34: Subtask load_data_to_prod_db
[2025-03-27T23:36:45.805+0000] {task_command.py:467} INFO - Running <TaskInstance: superstore_dag.load_data_to_prod_db manual__2025-03-27T23:36:31.455144+00:00 [running]> on host e0cefe7bdbf4
[2025-03-27T23:36:45.942+0000] {taskinstance.py:3131} INFO - Exporting env vars: AIRFLOW_CTX_DAG_OWNER='***' AIRFLOW_CTX_DAG_ID='superstore_dag' AIRFLOW_CTX_TASK_ID='load_data_to_prod_db' AIRFLOW_CTX_EXECUTION_DATE='2025-03-27T23:36:31.455144+00:00' AIRFLOW_CTX_TRY_NUMBER='1' AIRFLOW_CTX_DAG_RUN_ID='manual__2025-03-27T23:36:31.455144+00:00'
[2025-03-27T23:36:45.944+0000] {logging_mixin.py:190} INFO - Task instance is in running state
[2025-03-27T23:36:45.947+0000] {logging_mixin.py:190} INFO -  Previous state of the Task instance: queued
[2025-03-27T23:36:45.949+0000] {logging_mixin.py:190} INFO - Current task name:load_data_to_prod_db state:running start_date:2025-03-27 23:36:45.653040+00:00
[2025-03-27T23:36:45.951+0000] {logging_mixin.py:190} INFO - Dag name:superstore_dag and current dag run status:running
[2025-03-27T23:36:45.953+0000] {taskinstance.py:731} INFO - ::endgroup::
[2025-03-27T23:36:45.972+0000] {logging_mixin.py:190} INFO - Checking and potentially creating table: prod_fact_table
[2025-03-27T23:36:45.985+0000] {base.py:84} INFO - Retrieving connection 'mssql_default'
[2025-03-27T23:36:55.002+0000] {logging_mixin.py:190} INFO - Error creating table prod_fact_table: (20009, b'DB-Lib error message 20009, severity 9:\nUnable to connect: Adaptive Server is unavailable or does not exist (localhost)\nNet-Lib error during Connection refused (111)\nDB-Lib error message 20009, severity 9:\nUnable to connect: Adaptive Server is unavailable or does not exist (localhost)\nNet-Lib error during Connection refused (111)\n')
[2025-03-27T23:36:55.030+0000] {logging_mixin.py:190} INFO - Checking and potentially creating table: prod_dim_product
[2025-03-27T23:37:04.048+0000] {logging_mixin.py:190} INFO - Error creating table prod_dim_product: (20009, b'DB-Lib error message 20009, severity 9:\nUnable to connect: Adaptive Server is unavailable or does not exist (localhost)\nNet-Lib error during Connection refused (111)\nDB-Lib error message 20009, severity 9:\nUnable to connect: Adaptive Server is unavailable or does not exist (localhost)\nNet-Lib error during Connection refused (111)\n')
[2025-03-27T23:37:04.079+0000] {logging_mixin.py:190} INFO - Checking and potentially creating table: prod_dim_order
[2025-03-27T23:37:13.093+0000] {logging_mixin.py:190} INFO - Error creating table prod_dim_order: (20009, b'DB-Lib error message 20009, severity 9:\nUnable to connect: Adaptive Server is unavailable or does not exist (localhost)\nNet-Lib error during Connection refused (111)\nDB-Lib error message 20009, severity 9:\nUnable to connect: Adaptive Server is unavailable or does not exist (localhost)\nNet-Lib error during Connection refused (111)\n')
[2025-03-27T23:37:13.114+0000] {logging_mixin.py:190} INFO - Checking and potentially creating table: prod_dim_customer
[2025-03-27T23:37:22.130+0000] {logging_mixin.py:190} INFO - Error creating table prod_dim_customer: (20009, b'DB-Lib error message 20009, severity 9:\nUnable to connect: Adaptive Server is unavailable or does not exist (localhost)\nNet-Lib error during Connection refused (111)\nDB-Lib error message 20009, severity 9:\nUnable to connect: Adaptive Server is unavailable or does not exist (localhost)\nNet-Lib error during Connection refused (111)\n')
[2025-03-27T23:37:22.140+0000] {logging_mixin.py:190} INFO - Checking and potentially creating table: prod_dim_location
[2025-03-27T23:37:31.155+0000] {logging_mixin.py:190} INFO - Error creating table prod_dim_location: (20009, b'DB-Lib error message 20009, severity 9:\nUnable to connect: Adaptive Server is unavailable or does not exist (localhost)\nNet-Lib error during Connection refused (111)\nDB-Lib error message 20009, severity 9:\nUnable to connect: Adaptive Server is unavailable or does not exist (localhost)\nNet-Lib error during Connection refused (111)\n')
[2025-03-27T23:37:31.170+0000] {logging_mixin.py:190} INFO - Checking and potentially creating table: prod_dim_date
[2025-03-27T23:37:40.185+0000] {logging_mixin.py:190} INFO - Error creating table prod_dim_date: (20009, b'DB-Lib error message 20009, severity 9:\nUnable to connect: Adaptive Server is unavailable or does not exist (localhost)\nNet-Lib error during Connection refused (111)\nDB-Lib error message 20009, severity 9:\nUnable to connect: Adaptive Server is unavailable or does not exist (localhost)\nNet-Lib error during Connection refused (111)\n')
[2025-03-27T23:37:40.212+0000] {logging_mixin.py:190} INFO - Truncating table: prod_fact_table
[2025-03-27T23:37:49.226+0000] {taskinstance.py:3310} ERROR - Task failed with exception
Traceback (most recent call last):
  File "src/pymssql/_pymssql.pyx", line 650, in pymssql._pymssql.connect
  File "src/pymssql/_mssql.pyx", line 2158, in pymssql._mssql.connect
  File "src/pymssql/_mssql.pyx", line 712, in pymssql._mssql.MSSQLConnection.__init__
  File "src/pymssql/_mssql.pyx", line 1884, in pymssql._mssql.maybe_raise_MSSQLDatabaseException
  File "src/pymssql/_mssql.pyx", line 1901, in pymssql._mssql.raise_MSSQLDatabaseException
pymssql._mssql.MSSQLDatabaseException: (20009, b'DB-Lib error message 20009, severity 9:\nUnable to connect: Adaptive Server is unavailable or does not exist (localhost)\nNet-Lib error during Connection refused (111)\nDB-Lib error message 20009, severity 9:\nUnable to connect: Adaptive Server is unavailable or does not exist (localhost)\nNet-Lib error during Connection refused (111)\n')

During handling of the above exception, another exception occurred:

Traceback (most recent call last):
  File "/home/airflow/.local/lib/python3.9/site-packages/airflow/models/taskinstance.py", line 767, in _execute_task
    result = _execute_callable(context=context, **execute_callable_kwargs)
  File "/home/airflow/.local/lib/python3.9/site-packages/airflow/models/taskinstance.py", line 733, in _execute_callable
    return ExecutionCallableRunner(
  File "/home/airflow/.local/lib/python3.9/site-packages/airflow/utils/operator_helpers.py", line 252, in run
    return self.func(*args, **kwargs)
  File "/home/airflow/.local/lib/python3.9/site-packages/airflow/models/baseoperator.py", line 406, in wrapper
    return func(self, *args, **kwargs)
  File "/home/airflow/.local/lib/python3.9/site-packages/airflow/operators/python.py", line 238, in execute
    return_value = self.execute_callable()
  File "/home/airflow/.local/lib/python3.9/site-packages/airflow/operators/python.py", line 256, in execute_callable
    return runner.run(*self.op_args, **self.op_kwargs)
  File "/home/airflow/.local/lib/python3.9/site-packages/airflow/utils/operator_helpers.py", line 252, in run
    return self.func(*args, **kwargs)
  File "/opt/airflow/dags/superstore_dag.py", line 206, in load_data_to_prod_db
    hook.run(f"TRUNCATE TABLE {target_table}")
  File "/home/airflow/.local/lib/python3.9/site-packages/airflow/providers/common/sql/hooks/sql.py", line 576, in run
    with self._create_autocommit_connection(autocommit) as conn:
  File "/usr/local/lib/python3.9/contextlib.py", line 119, in __enter__
    return next(self.gen)
  File "/home/airflow/.local/lib/python3.9/site-packages/airflow/providers/common/sql/hooks/sql.py", line 684, in _create_autocommit_connection
    with closing(self.get_conn()) as conn:
  File "/home/airflow/.local/lib/python3.9/site-packages/airflow/providers/microsoft/mssql/hooks/mssql.py", line 103, in get_conn
    return pymssql.connect(
  File "src/pymssql/_pymssql.pyx", line 659, in pymssql._pymssql.connect
pymssql.exceptions.OperationalError: (20009, b'DB-Lib error message 20009, severity 9:\nUnable to connect: Adaptive Server is unavailable or does not exist (localhost)\nNet-Lib error during Connection refused (111)\nDB-Lib error message 20009, severity 9:\nUnable to connect: Adaptive Server is unavailable or does not exist (localhost)\nNet-Lib error during Connection refused (111)\n')
[2025-03-27T23:37:49.261+0000] {logging_mixin.py:190} INFO - Task instance in failure state
[2025-03-27T23:37:49.264+0000] {logging_mixin.py:190} INFO - Task start:2025-03-27 23:36:45.653040+00:00 end:2025-03-27 23:37:49.260344+00:00 duration:63.607304
[2025-03-27T23:37:49.267+0000] {logging_mixin.py:190} INFO - Task:<Task(PythonOperator): load_data_to_prod_db> dag:<DAG: superstore_dag> dagrun:<DagRun superstore_dag @ 2025-03-27 23:36:31.455144+00:00: manual__2025-03-27T23:36:31.455144+00:00, state:running, queued_at: 2025-03-27 23:36:31.486428+00:00. externally triggered: True>
[2025-03-27T23:37:49.269+0000] {logging_mixin.py:190} INFO - Failure caused by (20009, b'DB-Lib error message 20009, severity 9:\nUnable to connect: Adaptive Server is unavailable or does not exist (localhost)\nNet-Lib error during Connection refused (111)\nDB-Lib error message 20009, severity 9:\nUnable to connect: Adaptive Server is unavailable or does not exist (localhost)\nNet-Lib error during Connection refused (111)\n')
[2025-03-27T23:37:49.272+0000] {taskinstance.py:1225} INFO - Marking task as UP_FOR_RETRY. dag_id=superstore_dag, task_id=load_data_to_prod_db, run_id=manual__2025-03-27T23:36:31.455144+00:00, execution_date=20250327T233631, start_date=20250327T233645, end_date=20250327T233749
[2025-03-27T23:37:49.299+0000] {taskinstance.py:340} INFO - ::group::Post task execution logs
[2025-03-27T23:37:49.302+0000] {standard_task_runner.py:124} ERROR - Failed to execute job 34 for task load_data_to_prod_db ((20009, b'DB-Lib error message 20009, severity 9:\nUnable to connect: Adaptive Server is unavailable or does not exist (localhost)\nNet-Lib error during Connection refused (111)\nDB-Lib error message 20009, severity 9:\nUnable to connect: Adaptive Server is unavailable or does not exist (localhost)\nNet-Lib error during Connection refused (111)\n'); 306)
Traceback (most recent call last):
  File "src/pymssql/_pymssql.pyx", line 650, in pymssql._pymssql.connect
  File "src/pymssql/_mssql.pyx", line 2158, in pymssql._mssql.connect
  File "src/pymssql/_mssql.pyx", line 712, in pymssql._mssql.MSSQLConnection.__init__
  File "src/pymssql/_mssql.pyx", line 1884, in pymssql._mssql.maybe_raise_MSSQLDatabaseException
  File "src/pymssql/_mssql.pyx", line 1901, in pymssql._mssql.raise_MSSQLDatabaseException
pymssql._mssql.MSSQLDatabaseException: (20009, b'DB-Lib error message 20009, severity 9:\nUnable to connect: Adaptive Server is unavailable or does not exist (localhost)\nNet-Lib error during Connection refused (111)\nDB-Lib error message 20009, severity 9:\nUnable to connect: Adaptive Server is unavailable or does not exist (localhost)\nNet-Lib error during Connection refused (111)\n')

During handling of the above exception, another exception occurred:

Traceback (most recent call last):
  File "/home/airflow/.local/lib/python3.9/site-packages/airflow/task/task_runner/standard_task_runner.py", line 117, in _start_by_fork
    ret = args.func(args, dag=self.dag)
  File "/home/airflow/.local/lib/python3.9/site-packages/airflow/cli/cli_config.py", line 49, in command
    return func(*args, **kwargs)
  File "/home/airflow/.local/lib/python3.9/site-packages/airflow/utils/cli.py", line 115, in wrapper
    return f(*args, **kwargs)
  File "/home/airflow/.local/lib/python3.9/site-packages/airflow/cli/commands/task_command.py", line 483, in task_run
    task_return_code = _run_task_by_selected_method(args, _dag, ti)
  File "/home/airflow/.local/lib/python3.9/site-packages/airflow/cli/commands/task_command.py", line 256, in _run_task_by_selected_method
    return _run_raw_task(args, ti)
  File "/home/airflow/.local/lib/python3.9/site-packages/airflow/cli/commands/task_command.py", line 341, in _run_raw_task
    return ti._run_raw_task(
  File "/home/airflow/.local/lib/python3.9/site-packages/airflow/utils/session.py", line 97, in wrapper
    return func(*args, session=session, **kwargs)
  File "/home/airflow/.local/lib/python3.9/site-packages/airflow/models/taskinstance.py", line 3004, in _run_raw_task
    return _run_raw_task(
  File "/home/airflow/.local/lib/python3.9/site-packages/airflow/models/taskinstance.py", line 273, in _run_raw_task
    TaskInstance._execute_task_with_callbacks(
  File "/home/airflow/.local/lib/python3.9/site-packages/airflow/models/taskinstance.py", line 3158, in _execute_task_with_callbacks
    result = self._execute_task(context, task_orig)
  File "/home/airflow/.local/lib/python3.9/site-packages/airflow/models/taskinstance.py", line 3182, in _execute_task
    return _execute_task(self, context, task_orig)
  File "/home/airflow/.local/lib/python3.9/site-packages/airflow/models/taskinstance.py", line 767, in _execute_task
    result = _execute_callable(context=context, **execute_callable_kwargs)
  File "/home/airflow/.local/lib/python3.9/site-packages/airflow/models/taskinstance.py", line 733, in _execute_callable
    return ExecutionCallableRunner(
  File "/home/airflow/.local/lib/python3.9/site-packages/airflow/utils/operator_helpers.py", line 252, in run
    return self.func(*args, **kwargs)
  File "/home/airflow/.local/lib/python3.9/site-packages/airflow/models/baseoperator.py", line 406, in wrapper
    return func(self, *args, **kwargs)
  File "/home/airflow/.local/lib/python3.9/site-packages/airflow/operators/python.py", line 238, in execute
    return_value = self.execute_callable()
  File "/home/airflow/.local/lib/python3.9/site-packages/airflow/operators/python.py", line 256, in execute_callable
    return runner.run(*self.op_args, **self.op_kwargs)
  File "/home/airflow/.local/lib/python3.9/site-packages/airflow/utils/operator_helpers.py", line 252, in run
    return self.func(*args, **kwargs)
  File "/opt/airflow/dags/superstore_dag.py", line 206, in load_data_to_prod_db
    hook.run(f"TRUNCATE TABLE {target_table}")
  File "/home/airflow/.local/lib/python3.9/site-packages/airflow/providers/common/sql/hooks/sql.py", line 576, in run
    with self._create_autocommit_connection(autocommit) as conn:
  File "/usr/local/lib/python3.9/contextlib.py", line 119, in __enter__
    return next(self.gen)
  File "/home/airflow/.local/lib/python3.9/site-packages/airflow/providers/common/sql/hooks/sql.py", line 684, in _create_autocommit_connection
    with closing(self.get_conn()) as conn:
  File "/home/airflow/.local/lib/python3.9/site-packages/airflow/providers/microsoft/mssql/hooks/mssql.py", line 103, in get_conn
    return pymssql.connect(
  File "src/pymssql/_pymssql.pyx", line 659, in pymssql._pymssql.connect
pymssql.exceptions.OperationalError: (20009, b'DB-Lib error message 20009, severity 9:\nUnable to connect: Adaptive Server is unavailable or does not exist (localhost)\nNet-Lib error during Connection refused (111)\nDB-Lib error message 20009, severity 9:\nUnable to connect: Adaptive Server is unavailable or does not exist (localhost)\nNet-Lib error during Connection refused (111)\n')
[2025-03-27T23:37:49.318+0000] {local_task_job_runner.py:266} INFO - Task exited with return code 1
[2025-03-27T23:37:49.337+0000] {taskinstance.py:3900} INFO - 0 downstream tasks scheduled from follow-on schedule check
[2025-03-27T23:37:49.359+0000] {local_task_job_runner.py:245} INFO - ::endgroup::
