[2025-03-28T21:19:19.849+0000] {local_task_job_runner.py:123} INFO - ::group::Pre task execution logs
[2025-03-28T21:19:19.911+0000] {taskinstance.py:2612} INFO - Dependencies all met for dep_context=non-requeueable deps ti=<TaskInstance: superstore_dag.forecast_aggregate_sales manual__2025-03-28T21:18:26.687999+00:00 [queued]>
[2025-03-28T21:19:19.941+0000] {taskinstance.py:2612} INFO - Dependencies all met for dep_context=requeueable deps ti=<TaskInstance: superstore_dag.forecast_aggregate_sales manual__2025-03-28T21:18:26.687999+00:00 [queued]>
[2025-03-28T21:19:19.958+0000] {taskinstance.py:2865} INFO - Starting attempt 1 of 2
[2025-03-28T21:19:20.029+0000] {taskinstance.py:2888} INFO - Executing <Task(PythonOperator): forecast_aggregate_sales> on 2025-03-28 21:18:26.687999+00:00
[2025-03-28T21:19:20.051+0000] {standard_task_runner.py:72} INFO - Started process 5508 to run task
[2025-03-28T21:19:20.062+0000] {standard_task_runner.py:104} INFO - Running: ['***', 'tasks', 'run', 'superstore_dag', 'forecast_aggregate_sales', 'manual__2025-03-28T21:18:26.687999+00:00', '--job-id', '194', '--raw', '--subdir', 'DAGS_FOLDER/superstore_dag.py', '--cfg-path', '/tmp/tmpstwy13nm']
[2025-03-28T21:19:20.071+0000] {standard_task_runner.py:105} INFO - Job 194: Subtask forecast_aggregate_sales
[2025-03-28T21:19:20.242+0000] {task_command.py:467} INFO - Running <TaskInstance: superstore_dag.forecast_aggregate_sales manual__2025-03-28T21:18:26.687999+00:00 [running]> on host b7fc87b83960
[2025-03-28T21:19:20.619+0000] {taskinstance.py:3131} INFO - Exporting env vars: AIRFLOW_CTX_DAG_OWNER='***' AIRFLOW_CTX_DAG_ID='superstore_dag' AIRFLOW_CTX_TASK_ID='forecast_aggregate_sales' AIRFLOW_CTX_EXECUTION_DATE='2025-03-28T21:18:26.687999+00:00' AIRFLOW_CTX_TRY_NUMBER='1' AIRFLOW_CTX_DAG_RUN_ID='manual__2025-03-28T21:18:26.687999+00:00'
[2025-03-28T21:19:20.630+0000] {logging_mixin.py:190} INFO - Task instance is in running state
[2025-03-28T21:19:20.638+0000] {logging_mixin.py:190} INFO -  Previous state of the Task instance: queued
[2025-03-28T21:19:20.640+0000] {logging_mixin.py:190} INFO - Current task name:forecast_aggregate_sales state:running start_date:2025-03-28 21:19:19.918596+00:00
[2025-03-28T21:19:20.651+0000] {logging_mixin.py:190} INFO - Dag name:superstore_dag and current dag run status:running
[2025-03-28T21:19:20.659+0000] {taskinstance.py:731} INFO - ::endgroup::
[2025-03-28T21:19:20.880+0000] {forecaster.py:961} INFO - Disabling daily seasonality. Run prophet with daily_seasonality=True to override this.
[2025-03-28T21:19:20.969+0000] {filesystem.py:118} DEBUG - input tempfile: /tmp/tmpc8_uv9a8/ixqdurk8.json
[2025-03-28T21:19:21.268+0000] {filesystem.py:118} DEBUG - input tempfile: /tmp/tmpc8_uv9a8/3h1hhlz_.json
[2025-03-28T21:19:21.272+0000] {model.py:2042} DEBUG - idx 0
[2025-03-28T21:19:21.289+0000] {model.py:2043} DEBUG - running CmdStan, num_threads: None
[2025-03-28T21:19:21.291+0000] {model.py:2055} DEBUG - CmdStan args: ['/home/***/.local/lib/python3.9/site-packages/prophet/stan_model/prophet_model.bin', 'random', 'seed=86165', 'data', 'file=/tmp/tmpc8_uv9a8/ixqdurk8.json', 'init=/tmp/tmpc8_uv9a8/3h1hhlz_.json', 'output', 'file=/tmp/tmpc8_uv9a8/prophet_model3f3liocl/prophet_model-20250328211921.csv', 'method=optimize', 'algorithm=lbfgs', 'iter=10000']
[2025-03-28T21:19:21.300+0000] {logging_mixin.py:190} WARNING - 21:19:21 - cmdstanpy - INFO - Chain [1] start processing
[2025-03-28T21:19:21.299+0000] {model.py:2058} INFO - Chain [1] start processing
[2025-03-28T21:19:21.671+0000] {logging_mixin.py:190} WARNING - 21:19:21 - cmdstanpy - INFO - Chain [1] done processing
[2025-03-28T21:19:21.671+0000] {model.py:2115} INFO - Chain [1] done processing
[2025-03-28T21:19:23.031+0000] {taskinstance.py:3310} ERROR - Task failed with exception
Traceback (most recent call last):
  File "/home/airflow/.local/lib/python3.9/site-packages/airflow/models/taskinstance.py", line 767, in _execute_task
    result = _execute_callable(context=context, **execute_callable_kwargs)
  File "/home/airflow/.local/lib/python3.9/site-packages/airflow/models/taskinstance.py", line 733, in _execute_callable
    return ExecutionCallableRunner(
  File "/home/airflow/.local/lib/python3.9/site-packages/airflow/utils/operator_helpers.py", line 252, in run
    return self.func(*args, **kwargs)
  File "/home/airflow/.local/lib/python3.9/site-packages/airflow/models/baseoperator.py", line 406, in wrapper
    return func(self, *args, **kwargs)
  File "/home/airflow/.local/lib/python3.9/site-packages/airflow/operators/python.py", line 238, in execute
    return_value = self.execute_callable()
  File "/home/airflow/.local/lib/python3.9/site-packages/airflow/operators/python.py", line 256, in execute_callable
    return runner.run(*self.op_args, **self.op_kwargs)
  File "/home/airflow/.local/lib/python3.9/site-packages/airflow/utils/operator_helpers.py", line 252, in run
    return self.func(*args, **kwargs)
  File "/opt/airflow/dags/superstore_dag.py", line 207, in forecast_aggregate_sales
    last_past_date = aggregate_sales_df_new['Order Date'].max().date()
AttributeError: 'str' object has no attribute 'date'
[2025-03-28T21:19:23.089+0000] {logging_mixin.py:190} INFO - Task instance in failure state
[2025-03-28T21:19:23.091+0000] {logging_mixin.py:190} INFO - Task start:2025-03-28 21:19:19.918596+00:00 end:2025-03-28 21:19:23.088696+00:00 duration:3.1701
[2025-03-28T21:19:23.092+0000] {logging_mixin.py:190} INFO - Task:<Task(PythonOperator): forecast_aggregate_sales> dag:<DAG: superstore_dag> dagrun:<DagRun superstore_dag @ 2025-03-28 21:18:26.687999+00:00: manual__2025-03-28T21:18:26.687999+00:00, state:running, queued_at: 2025-03-28 21:18:26.719934+00:00. externally triggered: True>
[2025-03-28T21:19:23.099+0000] {logging_mixin.py:190} INFO - Failure caused by 'str' object has no attribute 'date'
[2025-03-28T21:19:23.101+0000] {taskinstance.py:1225} INFO - Marking task as UP_FOR_RETRY. dag_id=superstore_dag, task_id=forecast_aggregate_sales, run_id=manual__2025-03-28T21:18:26.687999+00:00, execution_date=20250328T211826, start_date=20250328T211919, end_date=20250328T211923
[2025-03-28T21:19:23.192+0000] {taskinstance.py:340} INFO - ::group::Post task execution logs
[2025-03-28T21:19:23.200+0000] {standard_task_runner.py:124} ERROR - Failed to execute job 194 for task forecast_aggregate_sales ('str' object has no attribute 'date'; 5508)
Traceback (most recent call last):
  File "/home/airflow/.local/lib/python3.9/site-packages/airflow/task/task_runner/standard_task_runner.py", line 117, in _start_by_fork
    ret = args.func(args, dag=self.dag)
  File "/home/airflow/.local/lib/python3.9/site-packages/airflow/cli/cli_config.py", line 49, in command
    return func(*args, **kwargs)
  File "/home/airflow/.local/lib/python3.9/site-packages/airflow/utils/cli.py", line 115, in wrapper
    return f(*args, **kwargs)
  File "/home/airflow/.local/lib/python3.9/site-packages/airflow/cli/commands/task_command.py", line 483, in task_run
    task_return_code = _run_task_by_selected_method(args, _dag, ti)
  File "/home/airflow/.local/lib/python3.9/site-packages/airflow/cli/commands/task_command.py", line 256, in _run_task_by_selected_method
    return _run_raw_task(args, ti)
  File "/home/airflow/.local/lib/python3.9/site-packages/airflow/cli/commands/task_command.py", line 341, in _run_raw_task
    return ti._run_raw_task(
  File "/home/airflow/.local/lib/python3.9/site-packages/airflow/utils/session.py", line 97, in wrapper
    return func(*args, session=session, **kwargs)
  File "/home/airflow/.local/lib/python3.9/site-packages/airflow/models/taskinstance.py", line 3004, in _run_raw_task
    return _run_raw_task(
  File "/home/airflow/.local/lib/python3.9/site-packages/airflow/models/taskinstance.py", line 273, in _run_raw_task
    TaskInstance._execute_task_with_callbacks(
  File "/home/airflow/.local/lib/python3.9/site-packages/airflow/models/taskinstance.py", line 3158, in _execute_task_with_callbacks
    result = self._execute_task(context, task_orig)
  File "/home/airflow/.local/lib/python3.9/site-packages/airflow/models/taskinstance.py", line 3182, in _execute_task
    return _execute_task(self, context, task_orig)
  File "/home/airflow/.local/lib/python3.9/site-packages/airflow/models/taskinstance.py", line 767, in _execute_task
    result = _execute_callable(context=context, **execute_callable_kwargs)
  File "/home/airflow/.local/lib/python3.9/site-packages/airflow/models/taskinstance.py", line 733, in _execute_callable
    return ExecutionCallableRunner(
  File "/home/airflow/.local/lib/python3.9/site-packages/airflow/utils/operator_helpers.py", line 252, in run
    return self.func(*args, **kwargs)
  File "/home/airflow/.local/lib/python3.9/site-packages/airflow/models/baseoperator.py", line 406, in wrapper
    return func(self, *args, **kwargs)
  File "/home/airflow/.local/lib/python3.9/site-packages/airflow/operators/python.py", line 238, in execute
    return_value = self.execute_callable()
  File "/home/airflow/.local/lib/python3.9/site-packages/airflow/operators/python.py", line 256, in execute_callable
    return runner.run(*self.op_args, **self.op_kwargs)
  File "/home/airflow/.local/lib/python3.9/site-packages/airflow/utils/operator_helpers.py", line 252, in run
    return self.func(*args, **kwargs)
  File "/opt/airflow/dags/superstore_dag.py", line 207, in forecast_aggregate_sales
    last_past_date = aggregate_sales_df_new['Order Date'].max().date()
AttributeError: 'str' object has no attribute 'date'
[2025-03-28T21:19:23.252+0000] {local_task_job_runner.py:266} INFO - Task exited with return code 1
[2025-03-28T21:19:23.310+0000] {taskinstance.py:3900} INFO - 0 downstream tasks scheduled from follow-on schedule check
[2025-03-28T21:19:23.339+0000] {local_task_job_runner.py:245} INFO - ::endgroup::
