[2025-03-28T21:33:51.594+0000] {local_task_job_runner.py:123} INFO - ::group::Pre task execution logs
[2025-03-28T21:33:51.764+0000] {taskinstance.py:2612} INFO - Dependencies all met for dep_context=non-requeueable deps ti=<TaskInstance: superstore_dag.forecast_aggregate_sales manual__2025-03-28T21:25:57.343878+00:00 [queued]>
[2025-03-28T21:33:51.884+0000] {taskinstance.py:2612} INFO - Dependencies all met for dep_context=requeueable deps ti=<TaskInstance: superstore_dag.forecast_aggregate_sales manual__2025-03-28T21:25:57.343878+00:00 [queued]>
[2025-03-28T21:33:51.896+0000] {taskinstance.py:2865} INFO - Starting attempt 2 of 2
[2025-03-28T21:33:52.105+0000] {taskinstance.py:2888} INFO - Executing <Task(PythonOperator): forecast_aggregate_sales> on 2025-03-28 21:25:57.343878+00:00
[2025-03-28T21:33:52.216+0000] {standard_task_runner.py:72} INFO - Started process 5821 to run task
[2025-03-28T21:33:52.386+0000] {standard_task_runner.py:104} INFO - Running: ['***', 'tasks', 'run', 'superstore_dag', 'forecast_aggregate_sales', 'manual__2025-03-28T21:25:57.343878+00:00', '--job-id', '202', '--raw', '--subdir', 'DAGS_FOLDER/superstore_dag.py', '--cfg-path', '/tmp/tmphnxhr74r']
[2025-03-28T21:33:52.435+0000] {standard_task_runner.py:105} INFO - Job 202: Subtask forecast_aggregate_sales
[2025-03-28T21:33:53.355+0000] {task_command.py:467} INFO - Running <TaskInstance: superstore_dag.forecast_aggregate_sales manual__2025-03-28T21:25:57.343878+00:00 [running]> on host b7fc87b83960
[2025-03-28T21:33:55.535+0000] {taskinstance.py:3131} INFO - Exporting env vars: AIRFLOW_CTX_DAG_OWNER='***' AIRFLOW_CTX_DAG_ID='superstore_dag' AIRFLOW_CTX_TASK_ID='forecast_aggregate_sales' AIRFLOW_CTX_EXECUTION_DATE='2025-03-28T21:25:57.343878+00:00' AIRFLOW_CTX_TRY_NUMBER='2' AIRFLOW_CTX_DAG_RUN_ID='manual__2025-03-28T21:25:57.343878+00:00'
[2025-03-28T21:33:55.554+0000] {logging_mixin.py:190} INFO - Task instance is in running state
[2025-03-28T21:33:55.565+0000] {logging_mixin.py:190} INFO -  Previous state of the Task instance: queued
[2025-03-28T21:33:55.575+0000] {logging_mixin.py:190} INFO - Current task name:forecast_aggregate_sales state:running start_date:2025-03-28 21:33:51.774904+00:00
[2025-03-28T21:33:55.585+0000] {logging_mixin.py:190} INFO - Dag name:superstore_dag and current dag run status:running
[2025-03-28T21:33:55.595+0000] {taskinstance.py:731} INFO - ::endgroup::
[2025-03-28T21:33:56.174+0000] {forecaster.py:961} INFO - Disabling daily seasonality. Run prophet with daily_seasonality=True to override this.
[2025-03-28T21:33:56.705+0000] {filesystem.py:118} DEBUG - input tempfile: /tmp/tmpb8d40hua/39lt75ov.json
[2025-03-28T21:33:58.985+0000] {filesystem.py:118} DEBUG - input tempfile: /tmp/tmpb8d40hua/4f74dyyb.json
[2025-03-28T21:33:59.044+0000] {model.py:2042} DEBUG - idx 0
[2025-03-28T21:33:59.065+0000] {model.py:2043} DEBUG - running CmdStan, num_threads: None
[2025-03-28T21:33:59.094+0000] {model.py:2055} DEBUG - CmdStan args: ['/home/***/.local/lib/python3.9/site-packages/prophet/stan_model/prophet_model.bin', 'random', 'seed=15742', 'data', 'file=/tmp/tmpb8d40hua/39lt75ov.json', 'init=/tmp/tmpb8d40hua/4f74dyyb.json', 'output', 'file=/tmp/tmpb8d40hua/prophet_modelzjlcfkbl/prophet_model-20250328213359.csv', 'method=optimize', 'algorithm=lbfgs', 'iter=10000']
[2025-03-28T21:33:59.134+0000] {logging_mixin.py:190} WARNING - 21:33:59 - cmdstanpy - INFO - Chain [1] start processing
[2025-03-28T21:33:59.116+0000] {model.py:2058} INFO - Chain [1] start processing
[2025-03-28T21:34:00.045+0000] {logging_mixin.py:190} WARNING - 21:34:00 - cmdstanpy - INFO - Chain [1] done processing
[2025-03-28T21:34:00.044+0000] {model.py:2115} INFO - Chain [1] done processing
[2025-03-28T21:34:04.121+0000] {taskinstance.py:3310} ERROR - Task failed with exception
Traceback (most recent call last):
  File "/home/airflow/.local/lib/python3.9/site-packages/airflow/models/taskinstance.py", line 767, in _execute_task
    result = _execute_callable(context=context, **execute_callable_kwargs)
  File "/home/airflow/.local/lib/python3.9/site-packages/airflow/models/taskinstance.py", line 733, in _execute_callable
    return ExecutionCallableRunner(
  File "/home/airflow/.local/lib/python3.9/site-packages/airflow/utils/operator_helpers.py", line 252, in run
    return self.func(*args, **kwargs)
  File "/home/airflow/.local/lib/python3.9/site-packages/airflow/models/baseoperator.py", line 406, in wrapper
    return func(self, *args, **kwargs)
  File "/home/airflow/.local/lib/python3.9/site-packages/airflow/operators/python.py", line 238, in execute
    return_value = self.execute_callable()
  File "/home/airflow/.local/lib/python3.9/site-packages/airflow/operators/python.py", line 256, in execute_callable
    return runner.run(*self.op_args, **self.op_kwargs)
  File "/home/airflow/.local/lib/python3.9/site-packages/airflow/utils/operator_helpers.py", line 252, in run
    return self.func(*args, **kwargs)
  File "/opt/airflow/dags/superstore_dag.py", line 207, in forecast_aggregate_sales
    last_past_date = aggregate_sales_df_new['Order Date'].max().date()
AttributeError: 'str' object has no attribute 'date'
[2025-03-28T21:34:04.241+0000] {logging_mixin.py:190} INFO - Task instance in failure state
[2025-03-28T21:34:04.252+0000] {logging_mixin.py:190} INFO - Task start:2025-03-28 21:33:51.774904+00:00 end:2025-03-28 21:34:04.222683+00:00 duration:12.447779
[2025-03-28T21:34:04.281+0000] {logging_mixin.py:190} INFO - Task:<Task(PythonOperator): forecast_aggregate_sales> dag:<DAG: superstore_dag> dagrun:<DagRun superstore_dag @ 2025-03-28 21:25:57.343878+00:00: manual__2025-03-28T21:25:57.343878+00:00, state:running, queued_at: 2025-03-28 21:25:57.432906+00:00. externally triggered: True>
[2025-03-28T21:34:04.302+0000] {logging_mixin.py:190} INFO - Failure caused by 'str' object has no attribute 'date'
[2025-03-28T21:34:04.322+0000] {taskinstance.py:1225} INFO - Marking task as FAILED. dag_id=superstore_dag, task_id=forecast_aggregate_sales, run_id=manual__2025-03-28T21:25:57.343878+00:00, execution_date=20250328T212557, start_date=20250328T213351, end_date=20250328T213404
[2025-03-28T21:34:04.502+0000] {taskinstance.py:340} INFO - ::group::Post task execution logs
[2025-03-28T21:34:04.522+0000] {standard_task_runner.py:124} ERROR - Failed to execute job 202 for task forecast_aggregate_sales ('str' object has no attribute 'date'; 5821)
Traceback (most recent call last):
  File "/home/airflow/.local/lib/python3.9/site-packages/airflow/task/task_runner/standard_task_runner.py", line 117, in _start_by_fork
    ret = args.func(args, dag=self.dag)
  File "/home/airflow/.local/lib/python3.9/site-packages/airflow/cli/cli_config.py", line 49, in command
    return func(*args, **kwargs)
  File "/home/airflow/.local/lib/python3.9/site-packages/airflow/utils/cli.py", line 115, in wrapper
    return f(*args, **kwargs)
  File "/home/airflow/.local/lib/python3.9/site-packages/airflow/cli/commands/task_command.py", line 483, in task_run
    task_return_code = _run_task_by_selected_method(args, _dag, ti)
  File "/home/airflow/.local/lib/python3.9/site-packages/airflow/cli/commands/task_command.py", line 256, in _run_task_by_selected_method
    return _run_raw_task(args, ti)
  File "/home/airflow/.local/lib/python3.9/site-packages/airflow/cli/commands/task_command.py", line 341, in _run_raw_task
    return ti._run_raw_task(
  File "/home/airflow/.local/lib/python3.9/site-packages/airflow/utils/session.py", line 97, in wrapper
    return func(*args, session=session, **kwargs)
  File "/home/airflow/.local/lib/python3.9/site-packages/airflow/models/taskinstance.py", line 3004, in _run_raw_task
    return _run_raw_task(
  File "/home/airflow/.local/lib/python3.9/site-packages/airflow/models/taskinstance.py", line 273, in _run_raw_task
    TaskInstance._execute_task_with_callbacks(
  File "/home/airflow/.local/lib/python3.9/site-packages/airflow/models/taskinstance.py", line 3158, in _execute_task_with_callbacks
    result = self._execute_task(context, task_orig)
  File "/home/airflow/.local/lib/python3.9/site-packages/airflow/models/taskinstance.py", line 3182, in _execute_task
    return _execute_task(self, context, task_orig)
  File "/home/airflow/.local/lib/python3.9/site-packages/airflow/models/taskinstance.py", line 767, in _execute_task
    result = _execute_callable(context=context, **execute_callable_kwargs)
  File "/home/airflow/.local/lib/python3.9/site-packages/airflow/models/taskinstance.py", line 733, in _execute_callable
    return ExecutionCallableRunner(
  File "/home/airflow/.local/lib/python3.9/site-packages/airflow/utils/operator_helpers.py", line 252, in run
    return self.func(*args, **kwargs)
  File "/home/airflow/.local/lib/python3.9/site-packages/airflow/models/baseoperator.py", line 406, in wrapper
    return func(self, *args, **kwargs)
  File "/home/airflow/.local/lib/python3.9/site-packages/airflow/operators/python.py", line 238, in execute
    return_value = self.execute_callable()
  File "/home/airflow/.local/lib/python3.9/site-packages/airflow/operators/python.py", line 256, in execute_callable
    return runner.run(*self.op_args, **self.op_kwargs)
  File "/home/airflow/.local/lib/python3.9/site-packages/airflow/utils/operator_helpers.py", line 252, in run
    return self.func(*args, **kwargs)
  File "/opt/airflow/dags/superstore_dag.py", line 207, in forecast_aggregate_sales
    last_past_date = aggregate_sales_df_new['Order Date'].max().date()
AttributeError: 'str' object has no attribute 'date'
[2025-03-28T21:34:04.731+0000] {local_task_job_runner.py:266} INFO - Task exited with return code 1
[2025-03-28T21:34:04.902+0000] {local_task_job_runner.py:245} INFO - ::endgroup::
